<robot name='x500'>
 
  <pose>0.081775 -0.106837 0.24 0 -0 0</pose>
  <self_collide>0</self_collide>
  <static>0</static>
  
  <!-- Link and joints definitions -->
  
  <link name='base_link'>
    <inertial>
      <mass>2</mass>
      <inertia>
        <ixx>0.0216667</ixx>
        <ixy>0</ixy>
        <ixz>0</ixz>
        <iyy>0.0216667</iyy>
        <iyz>0</iyz>
        <izz>0.04</izz>
      </inertia>
      <pose>0 0 0 0 -0 0</pose>
    </inertial>
    <gravity>1</gravity>
    <velocity_decay/>
    <visual name='base_link_visual'>
      <pose>0 0 0.025 0 -0 -3.14159</pose>
      <geometry>
        <mesh>
          <scale>1 1 1</scale>
          <uri>https://fuel.ignitionrobotics.org/1.0/px4/models/x500/2/files/meshes/NXP-HGD-CF.dae</uri>
        </mesh>
      </geometry>
    </visual>
    <visual name='5010_motor_base_0'>
      <pose>0.174 0.174 0.032 0 0 -0.45</pose>
      <geometry>
        <mesh>
          <scale>1 1 1</scale>
          <uri>https://fuel.ignitionrobotics.org/1.0/px4/models/x500/2/files/meshes/5010Base.dae</uri>
        </mesh>
      </geometry>
    </visual>
    <visual name='5010_motor_base_1'>
      <pose>-0.174 0.174 0.032 0 0 -0.45</pose>
      <geometry>
        <mesh>
          <scale>1 1 1</scale>
          <uri>https://fuel.ignitionrobotics.org/1.0/px4/models/x500/2/files/meshes/5010Base.dae</uri>
        </mesh>
      </geometry>
    </visual>
    <visual name='5010_motor_base_2'>
      <pose>0.174 -0.174 0.032 0 0 -0.45</pose>
      <geometry>
        <mesh>
          <scale>1 1 1</scale>
          <uri>https://fuel.ignitionrobotics.org/1.0/px4/models/x500/2/files/meshes/5010Base.dae</uri>
        </mesh>
      </geometry>
    </visual>
    <visual name='5010_motor_base_3'>
      <pose>-0.174 -0.174 0.032 0 0 -0.45</pose>
      <geometry>
        <mesh>
          <scale>1 1 1</scale>
          <uri>https://fuel.ignitionrobotics.org/1.0/px4/models/x500/2/files/meshes/5010Base.dae</uri>
        </mesh>
      </geometry>
    </visual>
    <visual name='NXP_FMUK66_FRONT'>
      <pose>0.047 0.001 0.043 1 0 1.57</pose>
      <cast_shadows>0</cast_shadows>
      <geometry>
        <plane>
          <normal>0 0 1</normal>
          <size>0.013 0.007</size>
        </plane>
      </geometry>
      <material>
        <diffuse>1 1 1 1</diffuse>
        <specular>1 1 1 1</specular>
        <pbr>
          <metal>
            <albedo_map>https://fuel.ignitionrobotics.org/1.0/px4/models/x500/2/files/materials/textures/nxp.png</albedo_map>
          </metal>
        </pbr>
      </material>
    </visual>
    <visual name='NXP_FMUK66_TOP'>
      <pose>-0.023 0 0.0515 0 0 -1.57</pose>
      <cast_shadows>0</cast_shadows>
      <geometry>
        <plane>
          <normal>0 0 1</normal>
          <size>0.013 0.007</size>
        </plane>
      </geometry>
      <material>
        <diffuse>1 1 1 1</diffuse>
        <specular>1 1 1 1</specular>
        <pbr>
          <metal>
            <albedo_map>https://fuel.ignitionrobotics.org/1.0/px4/models/x500/2/files/materials/textures/nxp.png</albedo_map>
          </metal>
        </pbr>
      </material>
    </visual>
    <visual name='RDDRONE_FMUK66_TOP'>
      <pose>-0.03 0 0.0515 0 0 -1.57</pose>
      <cast_shadows>0</cast_shadows>
      <geometry>
        <plane>
          <normal>0 0 1</normal>
          <size>0.032 0.0034</size>
        </plane>
      </geometry>
      <material>
        <diffuse>1 1 1 1</diffuse>
        <specular>1 1 1 1</specular>
        <pbr>
          <metal>
            <albedo_map>https://fuel.ignitionrobotics.org/1.0/px4/models/x500/2/files/materials/textures/rd.png</albedo_map>
          </metal>
        </pbr>
      </material>
    </visual>
    <collision name='base_link_collision_0'>
      <pose>0 0 0.007 0 -0 0</pose>
      <geometry>
        <box>
          <size>0.353553 0.353553 0.05</size>
        </box>
      </geometry>
      <surface>
        <contact>
          <ode>
            <min_depth>0.001</min_depth>
            <max_vel>0</max_vel>
          </ode>
        </contact>
        <friction>
          <ode/>
          <torsional>
            <ode/>
          </torsional>
        </friction>
        <bounce/>
      </surface>
      <max_contacts>10</max_contacts>
    </collision>
    <collision name='base_link_collision_1'>
      <pose>0 -0.098 -0.123 -0.35 0 0</pose>
      <geometry>
        <box>
          <size>0.015 0.015 0.21</size>
        </box>
      </geometry>
      <surface>
        <contact>
          <ode>
            <min_depth>0.001</min_depth>
            <max_vel>0</max_vel>
          </ode>
        </contact>
        <friction>
          <ode/>
          <torsional>
            <ode/>
          </torsional>
        </friction>
        <bounce/>
      </surface>
      <max_contacts>10</max_contacts>
    </collision>
    <collision name='base_link_collision_2'>
      <pose>0 0.098 -0.123 0.35 -0 0</pose>
      <geometry>
        <box>
          <size>0.015 0.015 0.21</size>
        </box>
      </geometry>
      <surface>
        <contact>
          <ode>
            <min_depth>0.001</min_depth>
            <max_vel>0</max_vel>
          </ode>
        </contact>
        <friction>
          <ode/>
          <torsional>
            <ode/>
          </torsional>
        </friction>
        <bounce/>
      </surface>
      <max_contacts>10</max_contacts>
    </collision>
    <collision name='base_link_collision_3'>
      <pose>0 -0.132 -0.2195 0 -0 0</pose>
      <geometry>
        <box>
          <size>0.25 0.015 0.015</size>
        </box>
      </geometry>
      <surface>
        <contact>
          <ode>
            <min_depth>0.001</min_depth>
            <max_vel>0</max_vel>
          </ode>
        </contact>
        <friction>
          <ode/>
          <torsional>
            <ode/>
          </torsional>
        </friction>
        <bounce/>
      </surface>
      <max_contacts>10</max_contacts>
    </collision>
    <collision name='base_link_collision_4'>
      <pose>0 0.132 -0.2195 0 -0 0</pose>
      <geometry>
        <box>
          <size>0.25 0.015 0.015</size>
        </box>
      </geometry>
      <surface>
        <contact>
          <ode>
            <min_depth>0.001</min_depth>
            <max_vel>0</max_vel>
          </ode>
        </contact>
        <friction>
          <ode/>
          <torsional>
            <ode/>
          </torsional>
        </friction>
        <bounce/>
      </surface>
      <max_contacts>10</max_contacts>
    </collision>
    <sensor name='imu_sensor' type='imu'>
      <always_on>1</always_on>
      <update_rate>250</update_rate>
      <imu/>
    </sensor>
    <self_collide>0</self_collide>
    <enable_wind>0</enable_wind>
    <kinematic>0</kinematic>
  </link>

  <link name='rotor_0'>
    <gravity>1</gravity>
    <self_collide>0</self_collide>
    <velocity_decay/>
    <pose>0.174 -0.174 0.06 0 -0 0</pose>
    <inertial>
      <mass>0.0160769</mass>
      <inertia>
        <ixx>3.84649e-07</ixx>
        <iyy>2.61159e-05</iyy>
        <izz>2.64986e-05</izz>
        <ixy>0</ixy>
        <ixz>0</ixz>
        <iyz>0</iyz>
      </inertia>
      <pose>0 0 0 0 -0 0</pose>
    </inertial>
    <visual name='rotor_0_visual'>
      <pose>-0.022 -0.146385 -0.016 0 -0 0</pose>
      <geometry>
        <mesh>
          <scale>0.846154 0.846154 0.846154</scale>
          <uri>https://fuel.ignitionrobotics.org/1.0/px4/models/x500/2/files/meshes/1345_prop_ccw.stl</uri>
        </mesh>
      </geometry>
      <material>
        <script>
          <name>Gazebo/DarkGrey</name>
          <uri>file://media/materials/scripts/gazebo.material</uri>
        </script>
      </material>
    </visual>
    <visual name='rotor_0_visual_motor_bell'>
      <pose>0 0 -0.032 0 -0 0</pose>
      <geometry>
        <mesh>
          <scale>1 1 1</scale>
          <uri>https://fuel.ignitionrobotics.org/1.0/px4/models/x500/2/files/meshes/5010Bell.dae</uri>
        </mesh>
      </geometry>
    </visual>
    <collision name='rotor_0_collision'>
      <pose>0 0 0 0 -0 0</pose>
      <geometry>
        <box>
          <size>0.279231 0.016923 0.000846</size>
        </box>
      </geometry>
      <surface>
        <contact>
          <ode>
            <min_depth>0.001</min_depth>
            <max_vel>0</max_vel>
          </ode>
        </contact>
        <friction>
          <ode/>
          <torsional>
            <ode/>
          </torsional>
        </friction>
        <bounce/>
      </surface>
      <max_contacts>10</max_contacts>
    </collision>
    <enable_wind>0</enable_wind>
    <kinematic>0</kinematic>
  </link>

  <joint name='rotor_0_joint' type='revolute'>
    <parent>base_link</parent>
    <child>rotor_0</child>
    <axis>
      <xyz expressed_in='__model__'>0 0 1</xyz>
      <limit>
        <lower>-1e+16</lower>
        <upper>1e+16</upper>
      </limit>
      <dynamics>
        <spring_reference>0</spring_reference>
        <spring_stiffness>0</spring_stiffness>
      </dynamics>
    </axis>
  </joint>

  <link name='rotor_1'>
    <gravity>1</gravity>
    <self_collide>0</self_collide>
    <velocity_decay/>
    <pose>-0.174 0.174 0.06 0 -0 0</pose>
    <inertial>
      <mass>0.0160769</mass>
      <inertia>
        <ixx>3.84649e-07</ixx>
        <iyy>2.61159e-05</iyy>
        <izz>2.64986e-05</izz>
        <ixy>0</ixy>
        <ixz>0</ixz>
        <iyz>0</iyz>
      </inertia>
      <pose>0 0 0 0 -0 0</pose>
    </inertial>
    <visual name='rotor_1_visual'>
      <pose>-0.022 -0.146385 -0.016 0 -0 0</pose>
      <geometry>
        <mesh>
          <scale>0.846154 0.846154 0.846154</scale>
          <uri>https://fuel.ignitionrobotics.org/1.0/px4/models/x500/2/files/meshes/1345_prop_ccw.stl</uri>
        </mesh>
      </geometry>
      <material>
        <script>
          <name>Gazebo/DarkGrey</name>
          <uri>file://media/materials/scripts/gazebo.material</uri>
        </script>
      </material>
    </visual>
    <visual name='rotor_1_visual_motor_top'>
      <pose>0 0 -0.032 0 -0 0</pose>
      <geometry>
        <mesh>
          <scale>1 1 1</scale>
          <uri>https://fuel.ignitionrobotics.org/1.0/px4/models/x500/2/files/meshes/5010Bell.dae</uri>
        </mesh>
      </geometry>
    </visual>
    <collision name='rotor_1_collision'>
      <pose>0 0 0 0 -0 0</pose>
      <geometry>
        <box>
          <size>0.279231 0.016923 0.000846</size>
        </box>
      </geometry>
      <surface>
        <contact>
          <ode>
            <min_depth>0.001</min_depth>
            <max_vel>0</max_vel>
          </ode>
        </contact>
        <friction>
          <ode/>
          <torsional>
            <ode/>
          </torsional>
        </friction>
        <bounce/>
      </surface>
      <max_contacts>10</max_contacts>
    </collision>
    <enable_wind>0</enable_wind>
    <kinematic>0</kinematic>
  </link>

  <joint name='rotor_1_joint' type='revolute'>
    <parent>base_link</parent>
    <child>rotor_1</child>
    <axis>
      <xyz expressed_in='__model__'>0 0 1</xyz>
      <limit>
        <lower>-1e+16</lower>
        <upper>1e+16</upper>
      </limit>
      <dynamics>
        <spring_reference>0</spring_reference>
        <spring_stiffness>0</spring_stiffness>
      </dynamics>
    </axis>
  </joint>

  <link name='rotor_2'>
    <gravity>1</gravity>
    <self_collide>0</self_collide>
    <velocity_decay/>
    <pose>0.174 0.174 0.06 0 -0 0</pose>
    <inertial>
      <mass>0.0160769</mass>
      <inertia>
        <ixx>3.84649e-07</ixx>
        <iyy>2.61159e-05</iyy>
        <izz>2.64986e-05</izz>
        <ixy>0</ixy>
        <ixz>0</ixz>
        <iyz>0</iyz>
      </inertia>
      <pose>0 0 0 0 -0 0</pose>
    </inertial>
    <visual name='rotor_2_visual'>
      <pose>-0.022 -0.146385 -0.016 0 -0 0</pose>
      <geometry>
        <mesh>
          <scale>0.846154 0.846154 0.846154</scale>
          <uri>https://fuel.ignitionrobotics.org/1.0/px4/models/x500/2/files/meshes/1345_prop_cw.stl</uri>
        </mesh>
      </geometry>
      <material>
        <script>
          <name>Gazebo/DarkGrey</name>
          <uri>file://media/materials/scripts/gazebo.material</uri>
        </script>
      </material>
    </visual>
    <visual name='rotor_2_visual_motor_top'>
      <pose>0 0 -0.032 0 -0 0</pose>
      <geometry>
        <mesh>
          <scale>1 1 1</scale>
          <uri>https://fuel.ignitionrobotics.org/1.0/px4/models/x500/2/files/meshes/5010Bell.dae</uri>
        </mesh>
      </geometry>
    </visual>
    <collision name='rotor_2_collision'>
      <pose>0 0 0 0 -0 0</pose>
      <geometry>
        <box>
          <size>0.279231 0.016923 0.000846</size>
        </box>
      </geometry>
      <surface>
        <contact>
          <ode>
            <min_depth>0.001</min_depth>
            <max_vel>0</max_vel>
          </ode>
        </contact>
        <friction>
          <ode/>
          <torsional>
            <ode/>
          </torsional>
        </friction>
        <bounce/>
      </surface>
      <max_contacts>10</max_contacts>
    </collision>
    <enable_wind>0</enable_wind>
    <kinematic>0</kinematic>
  </link>

  <joint name='rotor_2_joint' type='revolute'>
    <parent>base_link</parent>
    <child>rotor_2</child>
    <axis>
      <xyz expressed_in='__model__'>0 0 1</xyz>
      <limit>
        <lower>-1e+16</lower>
        <upper>1e+16</upper>
      </limit>
      <dynamics>
        <spring_reference>0</spring_reference>
        <spring_stiffness>0</spring_stiffness>
      </dynamics>
    </axis>
  </joint>

  <link name='rotor_3'>
    <gravity>1</gravity>
    <self_collide>0</self_collide>
    <velocity_decay/>
    <pose>-0.174 -0.174 0.06 0 -0 0</pose>
    <inertial>
      <mass>0.0160769</mass>
      <inertia>
        <ixx>3.84649e-07</ixx>
        <iyy>2.61159e-05</iyy>
        <izz>2.64986e-05</izz>
        <ixy>0</ixy>
        <ixz>0</ixz>
        <iyz>0</iyz>
      </inertia>
      <pose>0 0 0 0 -0 0</pose>
    </inertial>
    <visual name='rotor_3_visual'>
      <pose>-0.022 -0.146385 -0.016 0 -0 0</pose>
      <geometry>
        <mesh>
          <scale>0.846154 0.846154 0.846154</scale>
          <uri>https://fuel.ignitionrobotics.org/1.0/px4/models/x500/2/files/meshes/1345_prop_cw.stl</uri>
        </mesh>
      </geometry>
      <material>
        <script>
          <name>Gazebo/DarkGrey</name>
          <uri>file://media/materials/scripts/gazebo.material</uri>
        </script>
      </material>
    </visual>
    <visual name='rotor_3_visual_motor_top'>
      <pose>0 0 -0.032 0 -0 0</pose>
      <geometry>
        <mesh>
          <scale>1 1 1</scale>
          <uri>https://fuel.ignitionrobotics.org/1.0/px4/models/x500/2/files/meshes/5010Bell.dae</uri>
        </mesh>
      </geometry>
    </visual>
    <collision name='rotor_3_collision'>
      <pose>0 0 0 0 -0 0</pose>
      <geometry>
        <box>
          <size>0.279231 0.016923 0.000846</size>
        </box>
      </geometry>
      <surface>
        <contact>
          <ode>
            <min_depth>0.001</min_depth>
            <max_vel>0</max_vel>
          </ode>
        </contact>
        <friction>
          <ode/>
          <torsional>
            <ode/>
          </torsional>
        </friction>
        <bounce/>
      </surface>
      <max_contacts>10</max_contacts>
    </collision>
    <enable_wind>0</enable_wind>
    <kinematic>0</kinematic>
  </link>

  <joint name='rotor_3_joint' type='revolute'>
    <parent>base_link</parent>
    <child>rotor_3</child>
    <axis>
      <xyz expressed_in='__model__'>0 0 1</xyz>
      <limit>
        <lower>-1e+16</lower>
        <upper>1e+16</upper>
      </limit>
      <dynamics>
        <spring_reference>0</spring_reference>
        <spring_stiffness>0</spring_stiffness>
      </dynamics>
    </axis>
  </joint>

  <!-- Plugins definitions -->

  <plugin name='ignition::gazebo::systems::Imu' filename='libignition-gazebo-imu-system.so'/>

  <plugin name='ignition::gazebo::systems::MulticopterMotorModel' filename='ignition-gazebo-multicopter-motor-model-system'>
    <robotNamespace>x500</robotNamespace>
    <jointName>rotor_0_joint</jointName>
    <linkName>rotor_0</linkName>
    <turningDirection>ccw</turningDirection>
    <timeConstantUp>0.0125</timeConstantUp>
    <timeConstantDown>0.025</timeConstantDown>
    <maxRotVelocity>1000.0</maxRotVelocity>
    <motorConstant>8.54858e-06</motorConstant>
    <momentConstant>0.016</momentConstant>
    <commandSubTopic>command/motor_speed</commandSubTopic>
    <motorNumber>0</motorNumber>
    <rotorDragCoefficient>8.06428e-05</rotorDragCoefficient>
    <rollingMomentCoefficient>1e-06</rollingMomentCoefficient>
    <rotorVelocitySlowdownSim>10</rotorVelocitySlowdownSim>
    <motorType>velocity</motorType>
  </plugin>
  
  <plugin name='ignition::gazebo::systems::MulticopterMotorModel' filename='ignition-gazebo-multicopter-motor-model-system'>
    <robotNamespace>x500</robotNamespace>
    <jointName>rotor_1_joint</jointName>
    <linkName>rotor_1</linkName>
    <turningDirection>ccw</turningDirection>
    <timeConstantUp>0.0125</timeConstantUp>
    <timeConstantDown>0.025</timeConstantDown>
    <maxRotVelocity>1000.0</maxRotVelocity>
    <motorConstant>8.54858e-06</motorConstant>
    <momentConstant>0.016</momentConstant>
    <commandSubTopic>command/motor_speed</commandSubTopic>
    <motorNumber>1</motorNumber>
    <rotorDragCoefficient>8.06428e-05</rotorDragCoefficient>
    <rollingMomentCoefficient>1e-06</rollingMomentCoefficient>
    <rotorVelocitySlowdownSim>10</rotorVelocitySlowdownSim>
    <motorType>velocity</motorType>
  </plugin>

  <plugin name='ignition::gazebo::systems::MulticopterMotorModel' filename='ignition-gazebo-multicopter-motor-model-system'>
    <robotNamespace>x500</robotNamespace>
    <jointName>rotor_2_joint</jointName>
    <linkName>rotor_2</linkName>
    <turningDirection>cw</turningDirection>
    <timeConstantUp>0.0125</timeConstantUp>
    <timeConstantDown>0.025</timeConstantDown>
    <maxRotVelocity>1000.0</maxRotVelocity>
    <motorConstant>8.54858e-06</motorConstant>
    <momentConstant>0.016</momentConstant>
    <commandSubTopic>command/motor_speed</commandSubTopic>
    <motorNumber>2</motorNumber>
    <rotorDragCoefficient>8.06428e-05</rotorDragCoefficient>
    <rollingMomentCoefficient>1e-06</rollingMomentCoefficient>
    <rotorVelocitySlowdownSim>10</rotorVelocitySlowdownSim>
    <motorType>velocity</motorType>
  </plugin>

  <plugin name='ignition::gazebo::systems::MulticopterMotorModel' filename='ignition-gazebo-multicopter-motor-model-system'>
    <robotNamespace>x500</robotNamespace>
    <jointName>rotor_3_joint</jointName>
    <linkName>rotor_3</linkName>
    <turningDirection>cw</turningDirection>
    <timeConstantUp>0.0125</timeConstantUp>
    <timeConstantDown>0.025</timeConstantDown>
    <maxRotVelocity>1000.0</maxRotVelocity>
    <motorConstant>8.54858e-06</motorConstant>
    <momentConstant>0.016</momentConstant>
    <commandSubTopic>command/motor_speed</commandSubTopic>
    <motorNumber>3</motorNumber>
    <rotorDragCoefficient>8.06428e-05</rotorDragCoefficient>
    <rollingMomentCoefficient>1e-06</rollingMomentCoefficient>
    <rotorVelocitySlowdownSim>10</rotorVelocitySlowdownSim>
    <motorType>velocity</motorType>
  </plugin>

</robot>
